#VRML_SIM R2019a utf8
WorldInfo {
}
Viewpoint {
  orientation -0.984587238403511 -0.17021222099575004 -0.04019663912122218 0.5920236465368706
  position 0.018948140297849553 0.3817147169530041 0.6608701192213816
}
TexturedBackground {
}
TexturedBackgroundLight {
}
Floor {
}
Robot {
  translation 0 0.075 0
  children [
    DEF BODY_GROUP Group {
      children [
        Shape {
          appearance PBRAppearance {
            baseColor 1 0 0
          }
          geometry Box {
            size 0.25 0.08 0.08
          }
        }
        Transform {
          translation 0.107 -0.0575 0
          children [
            Shape {
              appearance PBRAppearance {
              }
              geometry Sphere {
                radius 0.0175
                subdivision 2
              }
            }
          ]
        }
      ]
    }
    HingeJoint {
      jointParameters HingeJointParameters {
        axis 0 0 1
        anchor -0.05 0 0.065
      }
      device [
        RotationalMotor {
          name "motor_right"
          maxVelocity 52.35
          maxTorque 0.59317
        }
        PositionSensor {
          name "right_position_distance_sensor "
          resolution 1
        }
      ]
      endPoint Solid {
        translation -0.05 0 0.055
        rotation 1 0 0 1.5708
        children [
          DEF Wheel Shape {
            appearance PBRAppearance {
              baseColor 0 0 0
              roughness 1
            }
            geometry Cylinder {
              height 0.03
              radius 0.075
            }
          }
        ]
        boundingObject USE Wheel
        physics Physics {
        }
      }
    }
    HingeJoint {
      jointParameters HingeJointParameters {
        axis 0 0 1
        anchor -0.05 0 -0.065
      }
      device [
        RotationalMotor {
          name "motor_left"
          maxVelocity 52.35
          maxTorque 0.593
        }
        PositionSensor {
          name "left_positon_sensor "
          resolution 1
        }
      ]
      endPoint Solid {
        translation -0.05 0 -0.055
        rotation 1 0 0 1.5708
        children [
          USE Wheel
        ]
        name "solid(1)"
        boundingObject USE Wheel
        physics Physics {
        }
      }
    }
    DistanceSensor {
      translation 0.125 0 0
    }
  ]
  boundingObject USE BODY_GROUP
  physics Physics {
  }
}
